Workbook

Sheet 🎯 COMMAND CENTER
A1: 🔥 EDGE LINK COMMAND DASHBOARD | APRIL 2026 | ⬆️ ALL TARGETS +10%
A2: Frontline Director Command Center · Jim Lane – Edgelink Inc · 34 Stores
A4: 📊 DIRECTOR OVERVIEW — APRIL 2026 TARGETS
B5: 🏆 TOTAL BOXES (PBB Target) | C5: 📲 BTS TARGET | D5: 📶 HSI TARGET | E5: 🔄 VOICE TARGET | F5: 💜 MAGENTA TARGET | G5: # STORES | H5: 🟢 ON TRACK | I5: 🔴 NEEDS ACTION
B6: =SUM('📋 SCORECARD'!D3:D36) -> 4431 | C6: =SUM('📋 SCORECARD'!H3:H36) -> 1114 | D6: =SUM('📋 SCORECARD'!L3:L36) -> 303 | E6: =SUM('📋 SCORECARD'!P3:P36) -> 2375 | F6: =SUM('📋 SCORECARD'!T3:T36) -> 657 | G6: =COUNTA('📋 SCORECARD'!B3:B36) -> 34 | H6: =COUNTIF('📋 SCORECARD'!G3:G36,"✅ ON TRACK") -> 0 | I6: =COUNTIF('📋 SCORECARD'!G3:G36,"🚨 ALERT") -> 0
A7: 📈 STORE PERFORMANCE SUMMARY — PBB RANKING
A8: RK | B8: STORE | C8: REGION | D8: PBB TGT | E8: PBB ACT | F8: PBB GAP | G8: % TO GOAL | H8: BTS TGT | I8: BTS ACT
A9: ='📋 SCORECARD'!A3 -> RK | B9: ='📋 SCORECARD'!B3 -> STORE NAME | C9: ='📋 SCORECARD'!C3 -> REGION | D9: ='📋 SCORECARD'!D3 -> TARGET | E9: ='📋 SCORECARD'!E3 -> ACTUAL | F9: ='📋 SCORECARD'!F3 -> GAP | G9: ='📋 SCORECARD'!G3 -> STATUS | H9: ='📋 SCORECARD'!H3 -> TARGET | I9: ='📋 SCORECARD'!I3 -> ACTUAL
A10: ='📋 SCORECARD'!A4 -> 1 | B10: ='📋 SCORECARD'!B4 -> Kelley Sq – Kelley Sq Worcester, MA | C10: ='📋 SCORECARD'!C4 -> NE | D10: ='📋 SCORECARD'!D4 -> 262 | E10: ='📋 SCORECARD'!E4 -> 0 | F10: ='📋 SCORECARD'!F4 | G10: ='📋 SCORECARD'!G4 -> — | H10: ='📋 SCORECARD'!H4 -> 81 | I10: ='📋 SCORECARD'!I4 -> 0
A11: ='📋 SCORECARD'!A5 -> 2 | B11: ='📋 SCORECARD'!B5 -> Providence Pl – Providence, RI | C11: ='📋 SCORECARD'!C5 -> NE | D11: ='📋 SCORECARD'!D5 -> 226 | E11: ='📋 SCORECARD'!E5 -> 0 | F11: ='📋 SCORECARD'!F5 | G11: ='📋 SCORECARD'!G5 -> — | H11: ='📋 SCORECARD'!H5 -> 54 | I11: ='📋 SCORECARD'!I5 -> 0
A12: ='📋 SCORECARD'!A6 -> 3 | B12: ='📋 SCORECARD'!B6 -> Hartford Ave – Providence, RI | C12: ='📋 SCORECARD'!C6 -> NE | D12: ='📋 SCORECARD'!D6 -> 201 | E12: ='📋 SCORECARD'!E6 -> 0 | F12: ='📋 SCORECARD'!F6 | G12: ='📋 SCORECARD'!G6 -> — | H12: ='📋 SCORECARD'!H6 -> 54 | I12: ='📋 SCORECARD'!I6 -> 0
A13: ='📋 SCORECARD'!A7 -> 4 | B13: ='📋 SCORECARD'!B7 -> Holyoke Street – Holyoke Street Holyoke, MA | C13: ='📋 SCORECARD'!C7 -> NE | D13: ='📋 SCORECARD'!D7 -> 191 | E13: ='📋 SCORECARD'!E7 -> 0 | F13: ='📋 SCORECARD'!F7 | G13: ='📋 SCORECARD'!G7 -> — | H13: ='📋 SCORECARD'!H7 -> 48 | I13: ='📋 SCORECARD'!I7 -> 0
A14: ='📋 SCORECARD'!A8 -> 5 | B14: ='📋 SCORECARD'!B8 -> Granite St – Braintree, MA | C14: ='📋 SCORECARD'!C8 -> NE | D14: ='📋 SCORECARD'!D8 -> 190 | E14: ='📋 SCORECARD'!E8 -> 0 | F14: ='📋 SCORECARD'!F8 | G14: ='📋 SCORECARD'!G8 -> — | H14: ='📋 SCORECARD'!H8 -> 56 | I14: ='📋 SCORECARD'!I8 -> 0
A15: ='📋 SCORECARD'!A9 -> 6 | B15: ='📋 SCORECARD'!B9 -> S Frontage – New London, CT | C15: ='📋 SCORECARD'!C9 -> NE | D15: ='📋 SCORECARD'!D9 -> 186 | E15: ='📋 SCORECARD'!E9 -> 0 | F15: ='📋 SCORECARD'!F9 | G15: ='📋 SCORECARD'!G9 -> — | H15: ='📋 SCORECARD'!H9 -> 44 | I15: ='📋 SCORECARD'!I9 -> 0
A16: ='📋 SCORECARD'!A10 -> 7 | B16: ='📋 SCORECARD'!B10 -> Geyer Springs – Little Rock, AR | C16: ='📋 SCORECARD'!C10 -> CENTRAL | D16: ='📋 SCORECARD'!D10 -> 182 | E16: ='📋 SCORECARD'!E10 -> 0 | F16: ='📋 SCORECARD'!F10 | G16: ='📋 SCORECARD'!G10 -> — | H16: ='📋 SCORECARD'!H10 -> 47 | I16: ='📋 SCORECARD'!I10 -> 0
A17: ='📋 SCORECARD'!A11 -> 8 | B17: ='📋 SCORECARD'!B11 -> E Magnolia – Knoxville, TN | C17: ='📋 SCORECARD'!C11 -> CENTRAL | D17: ='📋 SCORECARD'!D11 -> 182 | E17: ='📋 SCORECARD'!E11 -> 0 | F17: ='📋 SCORECARD'!F11 | G17: ='📋 SCORECARD'!G11 -> — | H17: ='📋 SCORECARD'!H11 -> 42 | I17: ='📋 SCORECARD'!I11 -> 0
A18: ='📋 SCORECARD'!A12 -> 9 | B18: ='📋 SCORECARD'!B12 -> N Broadway – Knoxville, TN | C18: ='📋 SCORECARD'!C12 -> CENTRAL | D18: ='📋 SCORECARD'!D12 -> 169 | E18: ='📋 SCORECARD'!E12 -> 0 | F18: ='📋 SCORECARD'!F12 | G18: ='📋 SCORECARD'!G12 -> — | H18: ='📋 SCORECARD'!H12 -> 35 | I18: ='📋 SCORECARD'!I12 -> 0
A19: ='📋 SCORECARD'!A13 -> 10 | B19: ='📋 SCORECARD'!B13 -> Iyannough Rd., – Hyannis, MA | C19: ='📋 SCORECARD'!C13 -> NE | D19: ='📋 SCORECARD'!D13 -> 161 | E19: ='📋 SCORECARD'!E13 -> 0 | F19: ='📋 SCORECARD'!F13 | G19: ='📋 SCORECARD'!G13 -> — | H19: ='📋 SCORECARD'!H13 -> 36 | I19: ='📋 SCORECARD'!I13 -> 0
A20: ='📋 SCORECARD'!A14 -> 11 | B20: ='📋 SCORECARD'!B14 -> Coggeshall St – New Bedford, MA | C20: ='📋 SCORECARD'!C14 -> NE | D20: ='📋 SCORECARD'!D14 -> 153 | E20: ='📋 SCORECARD'!E14 -> 0 | F20: ='📋 SCORECARD'!F14 | G20: ='📋 SCORECARD'!G14 -> — | H20: ='📋 SCORECARD'!H14 -> 38 | I20: ='📋 SCORECARD'!I14 -> 0
... A42: ='📋 SCORECARD'!A36 -> 33 | B42: ='📋 SCORECARD'!B36 -> W Andrew – Morristown, TN | C42: ='📋 SCORECARD'!C36 -> CENTRAL | D42: ='📋 SCORECARD'!D36 -> 69 | E42: ='📋 SCORECARD'!E36 -> 0 | F42: ='📋 SCORECARD'!F36 | G42: ='📋 SCORECARD'!G36 -> — | H42: ='📋 SCORECARD'!H36 -> 16 | I42: ='📋 SCORECARD'!I36 -> 0

Sheet 📋 SCORECARD
A1: 📋 STORE SCORECARD | EDGE LINK INC | APRIL 2026 | 34 STORES | ⬆️ TARGETS +10%
A2: RK | B2: STORE NAME | C2: REGION | D2: 🏆 PBB (TOTAL BOXES) | H2: 📲 BTS (TABLETS) | L2: 📶 HSI (HINT) | P2: 🔊 VOICE ACTS | T2: 💜 MAGENTA/MIMS | X2: OVERALL % | Y2: ⚠️ ALERT FLAGS
A3: RK | B3: STORE NAME | C3: REGION | D3: TARGET | E3: ACTUAL | F3: GAP | G3: STATUS | H3: TARGET | I3: ACTUAL | J3: GAP | K3: STATUS | L3: TARGET | M3: ACTUAL | N3: GAP | O3: STATUS | P3: TARGET | Q3: ACTUAL | R3: GAP | S3: STATUS | T3: TARGET | U3: ACTUAL | V3: GAP | W3: STATUS | X3: OVERALL % | Y3: ALERT FLAGS | Z3: TEAM (Week of 3/30)
A4: 1 | B4: Kelley Sq – Kelley Sq Worcester, MA | C4: NE | D4: 262 | F4: =IF(E4="","",E4-D4) | G4: =IF(OR(E4="",D4=0),"—",IF(E4/D4>=0.9,"✅ ON TRACK",IF(E4/D4>=0.7,"⚠️ WATCH","🚨 ALERT"))) -> — | H4: 81 | J4: =IF(I4="","",I4-H4) | K4: =IF(OR(I4="",H4=0),"—",IF(I4/H4>=0.9,"✅ ON TRACK",IF(I4/H4>=0.7,"⚠️ WATCH","🚨 ALERT"))) -> — | L4: 16 | N4: =IF(M4="","",M4-L4) | O4: =IF(OR(M4="",L4=0),"—",IF(M4/L4>=0.9,"✅ ON TRACK",IF(M4/L4>=0.7,"⚠️ WATCH","🚨 ALERT"))) -> — | P4: 125 | R4: =IF(Q4="","",Q4-P4) | S4: =IF(OR(Q4="",P4=0),"—",IF(Q4/P4>=0.9,"✅ ON TRACK",IF(Q4/P4>=0.7,"⚠️ WATCH","🚨 ALERT"))) -> — | T4: 30 | V4: =IF(U4="","",U4-T4) | W4: =IF(OR(U4="",T4=0),"—",IF(U4/T4>=0.9,"✅ ON TRACK",IF(U4/T4>=0.7,"⚠️ WATCH","🚨 ALERT"))) -> — | X4: =IFERROR(AVERAGE(IF(E4<>"",E4/D4),IF(I4<>"",I4/H4),IF(M4<>"",M4/L4),IF(Q4<>"",Q4/P4),IF(U4<>"",U4/T4)),"") -> 0 | Y4: =IFERROR(IF(AND(E4<>"",I4<>"",E4/D4>0.9,I4/H4<0.7),"⚠️ Volume w/o BTS | ","")&IF(AND(M4<>"",M4=0),"🚨 ZERO HSI | ","")&IF(AND(I4<>"",I4=0),"🚨 ZERO BTS | ","")&IF(AND(E4<>"",U4<>"",E4/D4>0.8,U4/T4<0.6),"⚠️ Weak MIMS | ","")&IF(AND(E4<>"",M4<>"",E4/D4>0.85,M4/L4<0.65),"⚠️ No Full Solution | ",""),"—") | Z4: Mariah Gonzalez, Richard Foster, Alex Correa, Juliana Arruda
A5: 2 | B5: Providence Pl – Providence, RI | C5: NE | D5: 226 | F5: =IF(E5="","",E5-D5) | G5: =IF(OR(E5="",D5=0),"—",IF(E5/D5>=0.9,"✅ ON TRACK",IF(E5/D5>=0.7,"⚠️ WATCH","🚨 ALERT"))) -> — | H5: 54 | J5: =IF(I5="","",I5-H5) | K5: =IF(OR(I5="",H5=0),"—",IF(I5/H5>=0.9,"✅ ON TRACK",IF(I5/H5>=0.7,"⚠️ WATCH","🚨 ALERT"))) -> — | L5: 17 | N5: =IF(M5="","",M5-L5) | O5: =IF(OR(M5="",L5=0),"—",IF(M5/L5>=0.9,"✅ ON TRACK",IF(M5/L5>=0.7,"⚠️ WATCH","🚨 ALERT"))) -> — | P5: 118 | R5: =IF(Q5="","",Q5-P5) | S5: =IF(OR(Q5="",P5=0),"—",IF(Q5/P5>=0.9,"✅ ON TRACK",IF(Q5/P5>=0.7,"⚠️ WATCH","🚨 ALERT"))) -> — | T5: 39 | V5: =IF(U5="","",U5-T5) | W5: =IF(OR(U5="",T5=0),"—",IF(U5/T5>=0.9,"✅ ON TRACK",IF(U5/T5>=0.7,"⚠️ WATCH","🚨 ALERT"))) -> — | X5: =IFERROR(AVERAGE(IF(E5<>"",E5/D5),IF(I5<>"",I5/H5),IF(M5<>"",M5/L5),IF(Q5<>"",Q5/P5),IF(U5<>"",U5/T5)),"") -> 0 | Y5: =IFERROR(IF(AND(E5<>"",I5<>"",E5/D5>0.9,I5/H5<0.7),"⚠️ Volume w/o BTS | ","")&IF(AND(M5<>"",M5=0),"🚨 ZERO HSI | ","")&IF(AND(I5<>"",I5=0),"🚨 ZERO BTS | ","")&IF(AND(E5<>"",U5<>"",E5/D5>0.8,U5/T5<0.6),"⚠️ Weak MIMS | ","")&IF(AND(E5<>"",M5<>"",E5/D5>0.85,M5/L5<0.65),"⚠️ No Full Solution | ",""),"—") | Z5: Abigail Baez, Kadisha Rivera, Brandon Mitchell, Juliana Arruda, Jason Link Jr
A6: 3 | B6: Hartford Ave – Providence, RI | C6: NE | D6: 201 | F6: =IF(E6="","",E6-D6) | G6: =IF(OR(E6="",D6=0),"—",IF(E6/D6>=0.9,"✅ ON TRACK",IF(E6/D6>=0.7,"⚠️ WATCH","🚨 ALERT"))) -> — | H6: 54 | J6: =IF(I6="","",I6-H6) | K6: =IF(OR(I6="",H6=0),"—",IF(I6/H6>=0.9,"✅ ON TRACK",IF(I6/H6>=0.7,"⚠️ WATCH","🚨 ALERT"))) -> — | L6: 10 | N6: =IF(M6="","",M6-L6) | O6: =IF(OR(M6="",L6=0),"—",IF(M6/L6>=0.9,"✅ ON TRACK",IF(M6/L6>=0.7,"⚠️ WATCH","🚨 ALERT"))) -> — | P6: 104 | R6: =IF(Q6="","",Q6-P6) | S6: =IF(OR(Q6="",P6=0),"—",IF(Q6/P6>=0.9,"✅ ON TRACK",IF(Q6/P6>=0.7,"⚠️ WATCH","🚨 ALERT"))) -> — | T6: 27 | V6: =IF(U6="","",U6-T6) | W6: =IF(OR(U6="",T6=0),"—",IF(U6/T6>=0.9,"✅ ON TRACK",IF(U6/T6>=0.7,"⚠️ WATCH","🚨 ALERT"))) -> — | X6: =IFERROR(AVERAGE(IF(E6<>"",E6/D6),IF(I6<>"",I6/H6),IF(M6<>"",M6/L6),IF(Q6<>"",Q6/P6),IF(U6<>"",U6/T6)),"") -> 0 | Y6: =IFERROR(IF(AND(E6<>"",I6<>"",E6/D6>0.9,I6/H6<0.7),"⚠️ Volume w/o BTS | ","")&IF(AND(M6<>"",M6=0),"🚨 ZERO HSI | ","")&IF(AND(I6<>"",I6=0),"🚨 ZERO BTS | ","")&IF(AND(E6<>"",U6<>"",E6/D6>0.8,U6/T6<0.6),"⚠️ Weak MIMS | ","")&IF(AND(E6<>"",M6<>"",E6/D6>0.85,M6/L6<0.65),"⚠️ No Full Solution | ",""),"—") | Z6: Oscar Mendez Muniz, Yanna Soriano, Milton Vega
A7: 4 | B7: Holyoke Street – Holyoke Street Holyoke, MA | C7: NE | D7: 191 | F7: =IF(E7="","",E7-D7) | G7: =IF(OR(E7="",D7=0),"—",IF(E7/D7>=0.9,"✅ ON TRACK",IF(E7/D7>=0.7,"⚠️ WATCH","🚨 ALERT"))) -> — | H7: 48 | J7: =IF(I7="","",I7-H7) | K7: =IF(OR(I7="",H7=0),"—",IF(I7/H7>=0.9,"✅ ON TRACK",IF(I7/H7>=0.7,"⚠️ WATCH","🚨 ALERT"))) -> — | L7: 9 | N7: =IF(M7="","",M7-L7) | O7: =IF(OR(M7="",L7=0),"—",IF(M7/L7>=0.9,"✅ ON TRACK",IF(M7/L7>=0.7,"⚠️ WATCH","🚨 ALERT"))) -> — | P7: 112 | R7: =IF(Q7="","",Q7-P7) | S7: =IF(OR(Q7="",P7=0),"—",IF(Q7/P7>=0.9,"✅ ON TRACK",IF(Q7/P7>=0.7,"⚠️ WATCH","🚨 ALERT"))) -> — | T7: 33 | V7: =IF(U7="","",U7-T7) | W7: =IF(OR(U7="",T7=0),"—",IF(U7/T7>=0.9,"✅ ON TRACK",IF(U7/T7>=0.7,"⚠️ WATCH","🚨 ALERT"))) -> — | X7: =IFERROR(AVERAGE(IF(E7<>"",E7/D7),IF(I7<>"",I7/H7),IF(M7<>"",M7/L7),IF(Q7<>"",Q7/P7),IF(U7<>"",U7/T7)),"") -> 0 | Y7: =IFERROR(IF(AND(E7<>"",I7<>"",E7/D7>0.9,I7/H7<0.7),"⚠️ Volume w/o BTS | ","")&IF(AND(M7<>"",M7=0),"🚨 ZERO HSI | ","")&IF(AND(I7<>"",I7=0),"🚨 ZERO BTS | ","")&IF(AND(E7<>"",U7<>"",E7/D7>0.8,U7/T7<0.6),"⚠️ Weak MIMS | ","")&IF(AND(E7<>"",M7<>"",E7/D7>0.85,M7/L7<0.65),"⚠️ No Full Solution | ",""),"—") | Z7: Carlos Davila, Hector Torres, Armando Perez
A8: 5 | B8: Granite St – Braintree, MA | C8: NE | D8: 190 | F8: =IF(E8="","",E8-D8) | G8: =IF(OR(E8="",D8=0),"—",IF(E8/D8>=0.9,"✅ ON TRACK",IF(E8/D8>=0.7,"⚠️ WATCH","🚨 ALERT"))) -> — | H8: 56 | J8: =IF(I8="","",I8-H8) | K8: =IF(OR(I8="",H8=0),"—",IF(I8/H8>=0.9,"✅ ON TRACK",IF(I8/H8>=0.7,"⚠️ WATCH","🚨 ALERT"))) -> — | L8: 11 | N8: =IF(M8="","",M8-L8) | O8: =IF(OR(M8="",L8=0),"—",IF(M8/L8>=0.9,"✅ ON TRACK",IF(M8/L8>=0.7,"⚠️ WATCH","🚨 ALERT"))) -> — | P8: 87 | R8: =IF(Q8="","",Q8-P8) | S8: =IF(OR(Q8="",P8=0),"—",IF(Q8/P8>=0.9,"✅ ON TRACK",IF(Q8/P8>=0.7,"⚠️ WATCH","🚨 ALERT"))) -> — | T8: 37 | V8: =IF(U8="","",U8-T8) | W8: =IF(OR(U8="",T8=0),"—",IF(U8/T8>=0.9,"✅ ON TRACK",IF(U8/T8>=0.7,"⚠️ WATCH","🚨 ALERT"))) -> — | X8: =IFERROR(AVERAGE(IF(E8<>"",E8/D8),IF(I8<>"",I8/H8),IF(M8<>"",M8/L8),IF(Q8<>"",Q8/P8),IF(U8<>"",U8/T8)),"") -> 0 | Y8: =IFERROR(IF(AND(E8<>"",I8<>"",E8/D8>0.9,I8/H8<0.7),"⚠️ Volume w/o BTS | ","")&IF(AND(M8<>"",M8=0),"🚨 ZERO HSI | ","")&IF(AND(I8<>"",I8=0),"🚨 ZERO BTS | ","")&IF(AND(E8<>"",U8<>"",E8/D8>0.8,U8/T8<0.6),"⚠️ Weak MIMS | ","")&IF(AND(E8<>"",M8<>"",E8/D8>0.85,M8/L8<0.65),"⚠️ No Full Solution | ",""),"—") | Z8: Yarele Soler, Abel Burgos, Amina Fellah, Lucmila Lopes
A9: 6 | B9: S Frontage – New London, CT | C9: NE | D9: 186 | F9: =IF(E9="","",E9-D9) | G9: =IF(OR(E9="",D9=0),"—",IF(E9/D9>=0.9,"✅ ON TRACK",IF(E9/D9>=0.7,"⚠️ WATCH","🚨 ALERT"))) -> — | H9: 44 | J9: =IF(I9="","",I9-H9) | K9: =IF(OR(I9="",H9=0),"—",IF(I9/H9>=0.9,"✅ ON TRACK",IF(I9/H9>=0.7,"⚠️ WATCH","🚨 ALERT"))) -> — | L9: 10 | N9: =IF(M9="","",M9-L9) | O9: =IF(OR(M9="",L9=0),"—",IF(M9/L9>=0.9,"✅ ON TRACK",IF(M9/L9>=0.7,"⚠️ WATCH","🚨 ALERT"))) -> — | P9: 104 | R9: =IF(Q9="","",Q9-P9) | S9: =IF(OR(Q9="",P9=0),"—",IF(Q9/P9>=0.9,"✅ ON TRACK",IF(Q9/P9>=0.7,"⚠️ WATCH","🚨 ALERT"))) -> — | T9: 27 | V9: =IF(U9="","",U9-T9) | W9: =IF(OR(U9="",T9=0),"—",IF(U9/T9>=0.9,"✅ ON TRACK",IF(U9/T9>=0.7,"⚠️ WATCH","🚨 ALERT"))) -> — | X9: =IFERROR(AVERAGE(IF(E9<>"",E9/D9),IF(I9<>"",I9/H9),IF(M9<>"",M9/L9),IF(Q9<>"",Q9/P9),IF(U9<>"",U9/T9)),"") -> 0 | Y9: =IFERROR(IF(AND(E9<>"",I9<>"",E9/D9>0.9,I9/H9<0.7),"⚠️ Volume w/o BTS | ","")&IF(AND(M9<>"",M9=0),"🚨 ZERO HSI | ","")&IF(AND(I9<>"",I9=0),"🚨 ZERO BTS | ","")&IF(AND(E9<>"",U9<>"",E9/D9>0.8,U9/T9<0.6),"⚠️ Weak MIMS | ","")&IF(AND(E9<>"",M9<>"",E9/D9>0.85,M9/L9<0.65),"⚠️ No Full Solution | ",""),"—") | Z9: James Garcia, Josh Landry, Rashia Oates, Shanelle Sanchez, Gilberto Alvarez
A10: 7 | B10: Geyer Springs – Little Rock, AR | C10: CENTRAL | D10: 182 | F10: =IF(E10="","",E10-D10) | G10: =IF(OR(E10="",D10=0),"—",IF(E10/D10>=0.9,"✅ ON TRACK",IF(E10/D10>=0.7,"⚠️ WATCH","🚨 ALERT"))) -> — | H10: 47 | J10: =IF(I10="","",I10-H10) | K10: =IF(OR(I10="",H10=0),"—",IF(I10/H10>=0.9,"✅ ON TRACK",IF(I10/H10>=0.7,"⚠️ WATCH","🚨 ALERT"))) -> — | L10: 17 | N10: =IF(M10="","",M10-L10) | O10: =IF(OR(M10="",L10=0),"—",IF(M10/L10>=0.9,"✅ ON TRACK",IF(M10/L10>=0.7,"⚠️ WATCH","🚨 ALERT"))) -> — | P10: 88 | R10: =IF(Q10="","",Q10-P10) | S10: =IF(OR(Q10="",P10=0),"—",IF(Q10/P10>=0.9,"✅ ON TRACK",IF(Q10/P10>=0.7,"⚠️ WATCH","🚨 ALERT"))) -> — | T10: 22 | V10: =IF(U10="","",U10-T10) | W10: =IF(OR(U10="",T10=0),"—",IF(U10/T10>=0.9,"✅ ON TRACK",IF(U10/T10>=0.7,"⚠️ WATCH","🚨 ALERT"))) -> — | X10: =IFERROR(AVERAGE(IF(E10<>"",E10/D10),IF(I10<>"",I10/H10),IF(M10<>"",M10/L10),IF(Q10<>"",Q10/P10),IF(U10<>"",U10/T10)),"") -> 0 | Y10: =IFERROR(IF(AND(E10<>"",I10<>"",E10/D10>0.9,I10/H10<0.7),"⚠️ Volume w/o BTS | ","")&IF(AND(M10<>"",M10=0),"🚨 ZERO HSI | ","")&IF(AND(I10<>"",I10=0),"🚨 ZERO BTS | ","")&IF(AND(E10<>"",U10<>"",E10/D10>0.8,U10/T10<0.6),"⚠️ Weak MIMS | ","")&IF(AND(E10<>"",M10<>"",E10/D10>0.85,M10/L10<0.65),"⚠️ No Full Solution | ",""),"—") | Z10: Melissa Sloane, Mariel Mcallister, Delbert Phillips
A11: 8 | B11: E Magnolia – Knoxville, TN | C11: CENTRAL | D11: 182 | F11: =IF(E11="","",E11-D11) | G11: =IF(OR(E11="",D11=0),"—",IF(E11/D11>=0.9,"✅ ON TRACK",IF(E11/D11>=0.7,"⚠️ WATCH","🚨 ALERT"))) -> — | H11: 42 | J11: =IF(I11="","",I11-H11) | K11: =IF(OR(I11="",H11=0),"—",IF(I11/H11>=0.9,"✅ ON TRACK",IF(I11/H11>=0.7,"⚠️ WATCH","🚨 ALERT"))) -> — | L11: 16 | N11: =IF(M11="","",M11-L11) | O11: =IF(OR(M11="",L11=0),"—",IF(M11/L11>=0.9,"✅ ON TRACK",IF(M11/L11>=0.7,"⚠️ WATCH","🚨 ALERT"))) -> — | P11: 104 | R11: =IF(Q11="","",Q11-P11) | S11: =IF(OR(Q11="",P11=0),"—",IF(Q11/P11>=0.9,"✅ ON TRACK",IF(Q11/P11>=0.7,"⚠️ WATCH","🚨 ALERT"))) -> — | T11: 19 | V11: =IF(U11="","",U11-T11) | W11: =IF(OR(U11="",T11=0),"—",IF(U11/T11>=0.9,"✅ ON TRACK",IF(U11/T11>=0.7,"⚠️ WATCH","🚨 ALERT"))) -> — | X11: =IFERROR(AVERAGE(IF(E11<>"",E11/D11),IF(I11<>"",I11/H11),IF(M11<>"",M11/L11),IF(Q11<>"",Q11/P11),IF(U11<>"",U11/T11)),"") -> 0 | Y11: =IFERROR(IF(AND(E11<>"",I11<>"",E11/D11>0.9,I11/H11<0.7),"⚠️ Volume w/o BTS | ","")&IF(AND(M11<>"",M11=0),"🚨 ZERO HSI | ","")&IF(AND(I11<>"",I11=0),"🚨 ZERO BTS | ","")&IF(AND(E11<>"",U11<>"",E11/D11>0.8,U11/T11<0.6),"⚠️ Weak MIMS | ","")&IF(AND(E11<>"",M11<>"",E11/D11>0.85,M11/L11<0.65),"⚠️ No Full Solution | ",""),"—") | Z11: Brenda Serna, Karmina Mendoza, Kevin Martinez, Jasmine Griffin
A12: 9 | B12: N Broadway – Knoxville, TN | C12: CENTRAL | D12: 169 | F12: =IF(E12="","",E12-D12) | G12: =IF(OR(E12="",D12=0),"—",IF(E12/D12>=0.9,"✅ ON TRACK",IF(E12/D12>=0.7,"⚠️ WATCH","🚨 ALERT"))) -> — | H12: 35 | J12: =IF(I12="","",I12-H12) | K12: =IF(OR(I12="",H12=0),"—",IF(I12/H12>=0.9,"✅ ON TRACK",IF(I12/H12>=0.7,"⚠️ WATCH","🚨 ALERT"))) -> — | L12: 16 | N12: =IF(M12="","",M12-L12) | O12: =IF(OR(M12="",L12=0),"—",IF(M12/L12>=0.9,"✅ ON TRACK",IF(M12/L12>=0.7,"⚠️ WATCH","🚨 ALERT"))) -> — | P12: 101 | R12: =IF(Q12="","",Q12-P12) | S12: =IF(OR(Q12="",P12=0),"—",IF(Q12/P12>=0.9,"✅ ON TRACK",IF(Q12/P12>=0.7,"⚠️ WATCH","🚨 ALERT"))) -> — | T12: 24 | V12: =IF(U12="","",U12-T12) | W12: =IF(OR(U12="",T12=0),"—",IF(U12/T12>=0.9,"✅ ON TRACK",IF(U12/T12>=0.7,"⚠️ WATCH","🚨 ALERT"))) -> — | X12: =IFERROR(AVERAGE(IF(E12<>"",E12/D12),IF(I12<>"",I12/H12),IF(M12<>"",M12/L12),IF(Q12<>"",Q12/P12),IF(U12<>"",U12/T12)),"") -> 0 | Y12: =IFERROR(IF(AND(E12<>"",I12<>"",E12/D12>0.9,I12/H12<0.7),"⚠️ Volume w/o BTS | ","")&IF(AND(M12<>"",M12=0),"🚨 ZERO HSI | ","")&IF(AND(I12<>"",I12=0),"🚨 ZERO BTS | ","")&IF(AND(E12<>"",U12<>"",E12/D12>0.8,U12/T12<0.6),"⚠️ Weak MIMS | ","")&IF(AND(E12<>"",M12<>"",E12/D12>0.85,M12/L12<0.65),"⚠️ No Full Solution | ",""),"—") | Z12: Shelena Hamilton, Franchesca Rader, Christopher Marion, April Mayorga
A13: 10 | B13: Iyannough Rd., – Hyannis, MA | C13: NE | D13: 161 | F13: =IF(E13="","",E13-D13) | G13: =IF(OR(E13="",D13=0),"—",IF(E13/D13>=0.9,"✅ ON TRACK",IF(E13/D13>=0.7,"⚠️ WATCH","🚨 ALERT"))) -> — | H13: 36 | J13: =IF(I13="","",I13-H13) | K13: =IF(OR(I13="",H13=0),"—",IF(I13/H13>=0.9,"✅ ON TRACK",IF(I13/H13>=0.7,"⚠️ WATCH","🚨 ALERT"))) -> — | L13: 9 | N13: =IF(M13="","",M13-L13) | O13: =IF(OR(M13="",L13=0),"—",IF(M13/L13>=0.9,"✅ ON TRACK",IF(M13/L13>=0.7,"⚠️ WATCH","🚨 ALERT"))) -> — | P13: 93 | R13: =IF(Q13="","",Q13-P13) | S13: =IF(OR(Q13="",P13=0),"—",IF(Q13/P13>=0.9,"✅ ON TRACK",IF(Q13/P13>=0.7,"⚠️ WATCH","🚨 ALERT"))) -> — | T13: 24 | V13: =IF(U13="","",U13-T13) | W13: =IF(OR(U13="",T13=0),"—",IF(U13/T13>=0.9,"✅ ON TRACK",IF(U13/T13>=0.7,"⚠️ WATCH","🚨 ALERT"))) -> — | X13: =IFERROR(AVERAGE(IF(E13<>"",E13/D13),IF(I13<>"",I13/H13),IF(M13<>"",M13/L13),IF(Q13<>"",Q13/P13),IF(U13<>"",U13/T13)),"") -> 0 | Y13: =IFERROR(IF(AND(E13<>"",I13<>"",E13/D13>0.9,I13/H13<0.7),"⚠️ Volume w/o BTS | ","")&IF(AND(M13<>"",M13=0),"🚨 ZERO HSI | ","")&IF(AND(I13<>"",I13=0),"🚨 ZERO BTS | ","")&IF(AND(E13<>"",U13<>"",E13/D13>0.8,U13/T13<0.6),"⚠️ Weak MIMS | ","")&IF(AND(E13<>"",M13<>"",E13/D13>0.85,M13/L13<0.65),"⚠️ No Full Solution | ",""),"—") | Z13: Maliek Feare, Jason Link Jr, Vernard Ashe
A14: 11 | B14: Coggeshall St – New Bedford, MA | C14: NE | D14: 153 | F14: =IF(E14="","",E14-D14) | G14: =IF(OR(E14="",D14=0),"—",IF(E14/D14>=0.9,"✅ ON TRACK",IF(E14/D14>=0.7,"⚠️ WATCH","🚨 ALERT"))) -> — | H14: 38 | J14: =IF(I14="","",I14-H14) | K14: =IF(OR(I14="",H14=0),"—",IF(I14/H14>=0.9,"✅ ON TRACK",IF(I14/H14>=0.7,"⚠️ WATCH","🚨 ALERT"))) -> — | L14: 9 | N14: =IF(M14="","",M14-L14) | O14: =IF(OR(M14="",L14=0),"—",IF(M14/L14>=0.9,"✅ ON TRACK",IF(M14/L14>=0.7,"⚠️ WATCH","🚨 ALERT"))) -> — | P14: 81 | R14: =IF(Q14="","",Q14-P14) | S14: =IF(OR(Q14="",P14=0),"—",IF(Q14/P14>=0.9,"✅ ON TRACK",IF(Q14/P14>=0.7,"⚠️ WATCH","🚨 ALERT"))) -> — | T14: 31 | V14: =IF(U14="","",U14-T14) | W14: =IF(OR(U14="",T14=0),"—",IF(U14/T14>=0.9,"✅ ON TRACK",IF(U14/T14>=0.7,"⚠️ WATCH","🚨 ALERT"))) -> — | X14: =IFERROR(AVERAGE(IF(E14<>"",E14/D14),IF(I14<>"",I14/H14),IF(M14<>"",M14/L14),IF(Q14<>"",Q14/P14),IF(U14<>"",U14/T14)),"") -> 0 | Y14: =IFERROR(IF(AND(E14<>"",I14<>"",E14/D14>0.9,I14/H14<0.7),"⚠️ Volume w/o BTS | ","")&IF(AND(M14<>"",M14=0),"🚨 ZERO HSI | ","")&IF(AND(I14<>"",I14=0),"🚨 ZERO BTS | ","")&IF(AND(E14<>"",U14<>"",E14/D14>0.8,U14/T14<0.6),"⚠️ Weak MIMS | ","")&IF(AND(E14<>"",M14<>"",E14/D14>0.85,M14/L14<0.65),"⚠️ No Full Solution | ",""),"—") | Z14: Napoleoa Dacruz, Djeison Barbosa, Khrystyne Quasney
A15: 12 | B15: Western Ave – Lynn, MA | C15: NE | D15: 141 | F15: =IF(E15="","",E15-D15) | G15: =IF(OR(E15="",D15=0),"—",IF(E15/D15>=0.9,"✅ ON TRACK",IF(E15/D15>=0.7,"⚠️ WATCH","🚨 ALERT"))) -> — | H15: 39 | J15: =IF(I15="","",I15-H15) | K15: =IF(OR(I15="",H15=0),"—",IF(I15/H15>=0.9,"✅ ON TRACK",IF(I15/H15>=0.7,"⚠️ WATCH","🚨 ALERT"))) -> — | L15: 8 | N15: =IF(M15="","",M15-L15) | O15: =IF(OR(M15="",L15=0),"—",IF(M15/L15>=0.9,"✅ ON TRACK",IF(M15/L15>=0.7,"⚠️ WATCH","🚨 ALERT"))) -> — | P15: 71 | R15: =IF(Q15="","",Q15-P15) | S15: =IF(OR(Q15="",P15=0),"—",IF(Q15/P15>=0.9,"✅ ON TRACK",IF(Q15/P15>=0.7,"⚠️ WATCH","🚨 ALERT"))) -> — | T15: 21 | V15: =IF(U15="","",U15-T15) | W15: =IF(OR(U15="",T15=0),"—",IF(U15/T15>=0.9,"✅ ON TRACK",IF(U15/T15>=0.7,"⚠️ WATCH","🚨 ALERT"))) -> — | X15: =IFERROR(AVERAGE(IF(E15<>"",E15/D15),IF(I15<>"",I15/H15),IF(M15<>"",M15/L15),IF(Q15<>"",Q15/P15),IF(U15<>"",U15/T15)),"") -> 0 | Y15: =IFERROR(IF(AND(E15<>"",I15<>"",E15/D15>0.9,I15/H15<0.7),"⚠️ Volume w/o BTS | ","")&IF(AND(M15<>"",M15=0),"🚨 ZERO HSI | ","")&IF(AND(I15<>"",I15=0),"🚨 ZERO BTS | ","")&IF(AND(E15<>"",U15<>"",E15/D15>0.8,U15/T15<0.6),"⚠️ Weak MIMS | ","")&IF(AND(E15<>"",M15<>"",E15/D15>0.85,M15/L15<0.65),"⚠️ No Full Solution | ",""),"—") | Z15: Stephanie Melo, Abel Burgos, Amina Fellah
... A37: 34 | B37: Tiogue Ave – Coventry, RI | C37: NE | D37: 59 | F37: =IF(E37="","",E37-D37) | G37: =IF(OR(E37="",D37=0),"—",IF(E37/D37>=0.9,"✅ ON TRACK",IF(E37/D37>=0.7,"⚠️ WATCH","🚨 ALERT"))) -> — | H37: 14 | J37: =IF(I37="","",I37-H37) | K37: =IF(OR(I37="",H37=0),"—",IF(I37/H37>=0.9,"✅ ON TRACK",IF(I37/H37>=0.7,"⚠️ WATCH","🚨 ALERT"))) -> — | L37: 4 | N37: =IF(M37="","",M37-L37) | O37: =IF(OR(M37="",L37=0),"—",IF(M37/L37>=0.9,"✅ ON TRACK",IF(M37/L37>=0.7,"⚠️ WATCH","🚨 ALERT"))) -> — | P37: 35 | R37: =IF(Q37="","",Q37-P37) | S37: =IF(OR(Q37="",P37=0),"—",IF(Q37/P37>=0.9,"✅ ON TRACK",IF(Q37/P37>=0.7,"⚠️ WATCH","🚨 ALERT"))) -> — | T37: 13 | V37: =IF(U37="","",U37-T37) | W37: =IF(OR(U37="",T37=0),"—",IF(U37/T37>=0.9,"✅ ON TRACK",IF(U37/T37>=0.7,"⚠️ WATCH","🚨 ALERT"))) -> — | X37: =IFERROR(AVERAGE(IF(E37<>"",E37/D37),IF(I37<>"",I37/H37),IF(M37<>"",M37/L37),IF(Q37<>"",Q37/P37),IF(U37<>"",U37/T37)),"") -> 0 | Y37: =IFERROR(IF(AND(E37<>"",I37<>"",E37/D37>0.9,I37/H37<0.7),"⚠️ Volume w/o BTS | ","")&IF(AND(M37<>"",M37=0),"🚨 ZERO HSI | ","")&IF(AND(I37<>"",I37=0),"🚨 ZERO BTS | ","")&IF(AND(E37<>"",U37<>"",E37/D37>0.8,U37/T37<0.6),"⚠️ Weak MIMS | ","")&IF(AND(E37<>"",M37<>"",E37/D37>0.85,M37/L37<0.65),"⚠️ No Full Solution | ",""),"—") | Z37: —
A38: TOTALS | D38: =SUM(D4:D37) -> 4490 | E38: =SUM(E4:E37) -> 0 | H38: =SUM(H4:H37) -> 1128 | I38: =SUM(I4:I37) -> 0 | L38: =SUM(L4:L37) -> 307 | M38: =SUM(M4:M37) -> 0 | P38: =SUM(P4:P37) -> 2410 | Q38: =SUM(Q4:Q37) -> 0 | T38: =SUM(T4:T37) -> 670 | U38: =SUM(U4:U37) -> 0

Sheet 🏆 RANKINGS
A1: 🏆 RANKINGS | EDGE LINK INC | APRIL 2026 (Updates automatically as actuals are entered)
A2: 🥇 TOP 10 STORES — PBB % TO GOAL | H2: 🔴 BOTTOM 10 STORES — NEED ATTENTION
A3: RK | B3: STORE | C3: REGION | D3: PBB TGT | E3: PBB ACT | F3: % TO GOAL | H3: RK | I3: STORE | J3: REGION | K3: PBB TGT | L3: PBB ACT | M3: % TO GOAL
A4: 1 | B4: ='📋 SCORECARD'!B4 -> Kelley Sq – Kelley Sq Worcester, MA | C4: ='📋 SCORECARD'!C4 -> NE | D4: ='📋 SCORECARD'!D4 -> 262 | E4: ='📋 SCORECARD'!E4 -> 0 | F4: =IFERROR('📋 SCORECARD'!E4/'📋 SCORECARD'!D4,"") -> 0 | H4: 1 | I4: ='📋 SCORECARD'!B37 -> Tiogue Ave – Coventry, RI | J4: ='📋 SCORECARD'!C37 -> NE | K4: ='📋 SCORECARD'!D37 -> 59 | L4: ='📋 SCORECARD'!E37 -> 0 | M4: =IFERROR('📋 SCORECARD'!E37/'📋 SCORECARD'!D37,"") -> 0
A5: 2 | B5: ='📋 SCORECARD'!B5 -> Providence Pl – Providence, RI | C5: ='📋 SCORECARD'!C5 -> NE | D5: ='📋 SCORECARD'!D5 -> 226 | E5: ='📋 SCORECARD'!E5 -> 0 | F5: =IFERROR('📋 SCORECARD'!E5/'📋 SCORECARD'!D5,"") -> 0 | H5: 2 | I5: ='📋 SCORECARD'!B36 -> W Andrew – Morristown, TN | J5: ='📋 SCORECARD'!C36 -> CENTRAL | K5: ='📋 SCORECARD'!D36 -> 69 | L5: ='📋 SCORECARD'!E36 -> 0 | M5: =IFERROR('📋 SCORECARD'!E36/'📋 SCORECARD'!D36,"") -> 0
A6: 3 | B6: ='📋 SCORECARD'!B6 -> Hartford Ave – Providence, RI | C6: ='📋 SCORECARD'!C6 -> NE | D6: ='📋 SCORECARD'!D6 -> 201 | E6: ='📋 SCORECARD'!E6 -> 0 | F6: =IFERROR('📋 SCORECARD'!E6/'📋 SCORECARD'!D6,"") -> 0 | H6: 3 | I6: ='📋 SCORECARD'!B35 -> Newport Ave – Rumford, RI | J6: ='📋 SCORECARD'!C35 -> NE | K6: ='📋 SCORECARD'!D35 -> 74 | L6: ='📋 SCORECARD'!E35 -> 0 | M6: =IFERROR('📋 SCORECARD'!E35/'📋 SCORECARD'!D35,"") -> 0
A7: 4 | B7: ='📋 SCORECARD'!B7 -> Holyoke Street – Holyoke Street Holyoke, MA | C7: ='📋 SCORECARD'!C7 -> NE | D7: ='📋 SCORECARD'!D7 -> 191 | E7: ='📋 SCORECARD'!E7 -> 0 | F7: =IFERROR('📋 SCORECARD'!E7/'📋 SCORECARD'!D7,"") -> 0 | H7: 4 | I7: ='📋 SCORECARD'!B34 -> W Market – Johnson City, TN | J7: ='📋 SCORECARD'!C34 -> CENTRAL | K7: ='📋 SCORECARD'!D34 -> 77 | L7: ='📋 SCORECARD'!E34 -> 0 | M7: =IFERROR('📋 SCORECARD'!E34/'📋 SCORECARD'!D34,"") -> 0
A8: 5 | B8: ='📋 SCORECARD'!B8 -> Granite St – Braintree, MA | C8: ='📋 SCORECARD'!C8 -> NE | D8: ='📋 SCORECARD'!D8 -> 190 | E8: ='📋 SCORECARD'!E8 -> 0 | F8: =IFERROR('📋 SCORECARD'!E8/'📋 SCORECARD'!D8,"") -> 0 | H8: 5 | I8: ='📋 SCORECARD'!B33 -> Douglas Ave – Providence, RI | J8: ='📋 SCORECARD'!C33 -> NE | K8: ='📋 SCORECARD'!D33 -> 83 | L8: ='📋 SCORECARD'!E33 -> 0 | M8: =IFERROR('📋 SCORECARD'!E33/'📋 SCORECARD'!D33,"") -> 0
A9: 6 | B9: ='📋 SCORECARD'!B9 -> S Frontage – New London, CT | C9: ='📋 SCORECARD'!C9 -> NE | D9: ='📋 SCORECARD'!D9 -> 186 | E9: ='📋 SCORECARD'!E9 -> 0 | F9: =IFERROR('📋 SCORECARD'!E9/'📋 SCORECARD'!D9,"") -> 0 | H9: 6 | I9: ='📋 SCORECARD'!B32 -> Colonel Glenn – Little Rock, AR | J9: ='📋 SCORECARD'!C32 -> CENTRAL | K9: ='📋 SCORECARD'!D32 -> 85 | L9: ='📋 SCORECARD'!E32 -> 0 | M9: =IFERROR('📋 SCORECARD'!E32/'📋 SCORECARD'!D32,"") -> 0
A10: 7 | B10: ='📋 SCORECARD'!B10 -> Geyer Springs – Little Rock, AR | C10: ='📋 SCORECARD'!C10 -> CENTRAL | D10: ='📋 SCORECARD'!D10 -> 182 | E10: ='📋 SCORECARD'!E10 -> 0 | F10: =IFERROR('📋 SCORECARD'!E10/'📋 SCORECARD'!D10,"") -> 0 | H10: 7 | I10: ='📋 SCORECARD'!B31 -> Broad St – Providence, RI | J10: ='📋 SCORECARD'!C31 -> NE | K10: ='📋 SCORECARD'!D31 -> 88 | L10: ='📋 SCORECARD'!E31 -> 0 | M10: =IFERROR('📋 SCORECARD'!E31/'📋 SCORECARD'!D31,"") -> 0
A11: 8 | B11: ='📋 SCORECARD'!B11 -> E Magnolia – Knoxville, TN | C11: ='📋 SCORECARD'!C11 -> CENTRAL | D11: ='📋 SCORECARD'!D11 -> 182 | E11: ='📋 SCORECARD'!E11 -> 0 | F11: =IFERROR('📋 SCORECARD'!E11/'📋 SCORECARD'!D11,"") -> 0 | H11: 8 | I11: ='📋 SCORECARD'!B30 -> Keith St – Cleveland, TN | J11: ='📋 SCORECARD'!C30 -> SE | K11: ='📋 SCORECARD'!D30 -> 92 | L11: ='📋 SCORECARD'!E30 -> 0 | M11: =IFERROR('📋 SCORECARD'!E30/'📋 SCORECARD'!D30,"") -> 0
A12: 9 | B12: ='📋 SCORECARD'!B12 -> N Broadway – Knoxville, TN | C12: ='📋 SCORECARD'!C12 -> CENTRAL | D12: ='📋 SCORECARD'!D12 -> 169 | E12: ='📋 SCORECARD'!E12 -> 0 | F12: =IFERROR('📋 SCORECARD'!E12/'📋 SCORECARD'!D12,"") -> 0 | H12: 9 | I12: ='📋 SCORECARD'!B29 -> Western Ave – Knoxville, TN | J12: ='📋 SCORECARD'!C29 -> CENTRAL | K12: ='📋 SCORECARD'!D29 -> 94 | L12: ='📋 SCORECARD'!E29 -> 0 | M12: =IFERROR('📋 SCORECARD'!E29/'📋 SCORECARD'!D29,"") -> 0
A13: 10 | B13: ='📋 SCORECARD'!B13 -> Iyannough Rd., – Hyannis, MA | C13: ='📋 SCORECARD'!C13 -> NE | D13: ='📋 SCORECARD'!D13 -> 161 | E13: ='📋 SCORECARD'!E13 -> 0 | F13: =IFERROR('📋 SCORECARD'!E13/'📋 SCORECARD'!D13,"") -> 0 | H13: 10 | I13: ='📋 SCORECARD'!B28 -> Locust St – Springfield, MA | J13: ='📋 SCORECARD'!C28 -> NE | K13: ='📋 SCORECARD'!D28 -> 94 | L13: ='📋 SCORECARD'!E28 -> 0 | M13: =IFERROR('📋 SCORECARD'!E28/'📋 SCORECARD'!D28,"") -> 0
A16: 📲 TOP 10 — BTS (TABLETS) % TO GOAL | H16: 📶 TOP 10 — HSI (HINT) % TO GOAL
A17: RK | B17: STORE | C17: REGION | D17: BTS TGT | E17: BTS ACT | F17: % TO GOAL | H17: RK | I17: STORE | J17: REGION | K17: HSI TGT | L17: HSI ACT | M17: % TO GOAL
A18: 1 | B18: ='📋 SCORECARD'!B4 -> Kelley Sq – Kelley Sq Worcester, MA | C18: ='📋 SCORECARD'!C4 -> NE | D18: ='📋 SCORECARD'!H4 -> 81 | E18: ='📋 SCORECARD'!I4 -> 0 | F18: =IFERROR('📋 SCORECARD'!I4/'📋 SCORECARD'!H4,"") -> 0 | H18: 1 | I18: ='📋 SCORECARD'!B4 -> Kelley Sq – Kelley Sq Worcester, MA | J18: ='📋 SCORECARD'!C4 -> NE | K18: ='📋 SCORECARD'!L4 -> 16 | L18: ='📋 SCORECARD'!M4 -> 0 | M18: =IFERROR('📋 SCORECARD'!M4/'📋 SCORECARD'!L4,"") -> 0
A19: 2 | B19: ='📋 SCORECARD'!B5 -> Providence Pl – Providence, RI | C19: ='📋 SCORECARD'!C5 -> NE | D19: ='📋 SCORECARD'!H5 -> 54 | E19: ='📋 SCORECARD'!I5 -> 0 | F19: =IFERROR('📋 SCORECARD'!I5/'📋 SCORECARD'!H5,"") -> 0 | H19: 2 | I19: ='📋 SCORECARD'!B5 -> Providence Pl – Providence, RI | J19: ='📋 SCORECARD'!C5 -> NE | K19: ='📋 SCORECARD'!L5 -> 17 | L19: ='📋 SCORECARD'!M5 -> 0 | M19: =IFERROR('📋 SCORECARD'!M5/'📋 SCORECARD'!L5,"") -> 0
A20: 3 | B20: ='📋 SCORECARD'!B6 -> Hartford Ave – Providence, RI | C20: ='📋 SCORECARD'!C6 -> NE | D20: ='📋 SCORECARD'!H6 -> 54 | E20: ='📋 SCORECARD'!I6 -> 0 | F20: =IFERROR('📋 SCORECARD'!I6/'📋 SCORECARD'!H6,"") -> 0 | H20: 3 | I20: ='📋 SCORECARD'!B6 -> Hartford Ave – Providence, RI | J20: ='📋 SCORECARD'!C6 -> NE | K20: ='📋 SCORECARD'!L6 -> 10 | L20: ='📋 SCORECARD'!M6 -> 0 | M20: =IFERROR('📋 SCORECARD'!M6/'📋 SCORECARD'!L6,"") -> 0
A21: 4 | B21: ='📋 SCORECARD'!B7 -> Holyoke Street – Holyoke Street Holyoke, MA | C21: ='📋 SCORECARD'!C7 -> NE | D21: ='📋 SCORECARD'!H7 -> 48 | E21: ='📋 SCORECARD'!I7 -> 0 | F21: =IFERROR('📋 SCORECARD'!I7/'📋 SCORECARD'!H7,"") -> 0 | H21: 4 | I21: ='📋 SCORECARD'!B7 -> Holyoke Street – Holyoke Street Holyoke, MA | J21: ='📋 SCORECARD'!C7 -> NE | K21: ='📋 SCORECARD'!L7 -> 9 | L21: ='📋 SCORECARD'!M7 -> 0 | M21: =IFERROR('📋 SCORECARD'!M7/'📋 SCORECARD'!L7,"") -> 0
A22: 5 | B22: ='📋 SCORECARD'!B8 -> Granite St – Braintree, MA | C22: ='📋 SCORECARD'!C8 -> NE | D22: ='📋 SCORECARD'!H8 -> 56 | E22: ='📋 SCORECARD'!I8 -> 0 | F22: =IFERROR('📋 SCORECARD'!I8/'📋 SCORECARD'!H8,"") -> 0 | H22: 5 | I22: ='📋 SCORECARD'!B8 -> Granite St – Braintree, MA | J22: ='📋 SCORECARD'!C8 -> NE | K22: ='📋 SCORECARD'!L8 -> 11 | L22: ='📋 SCORECARD'!M8 -> 0 | M22: =IFERROR('📋 SCORECARD'!M8/'📋 SCORECARD'!L8,"") -> 0
A23: 6 | B23: ='📋 SCORECARD'!B9 -> S Frontage – New London, CT | C23: ='📋 SCORECARD'!C9 -> NE | D23: ='📋 SCORECARD'!H9 -> 44 | E23: ='📋 SCORECARD'!I9 -> 0 | F23: =IFERROR('📋 SCORECARD'!I9/'📋 SCORECARD'!H9,"") -> 0 | H23: 6 | I23: ='📋 SCORECARD'!B9 -> S Frontage – New London, CT | J23: ='📋 SCORECARD'!C9 -> NE | K23: ='📋 SCORECARD'!L9 -> 10 | L23: ='📋 SCORECARD'!M9 -> 0 | M23: =IFERROR('📋 SCORECARD'!M9/'📋 SCORECARD'!L9,"") -> 0
A24: 7 | B24: ='📋 SCORECARD'!B10 -> Geyer Springs – Little Rock, AR | C24: ='📋 SCORECARD'!C10 -> CENTRAL | D24: ='📋 SCORECARD'!H10 -> 47 | E24: ='📋 SCORECARD'!I10 -> 0 | F24: =IFERROR('📋 SCORECARD'!I10/'📋 SCORECARD'!H10,"") -> 0 | H24: 7 | I24: ='📋 SCORECARD'!B10 -> Geyer Springs – Little Rock, AR | J24: ='📋 SCORECARD'!C10 -> CENTRAL | K24: ='📋 SCORECARD'!L10 -> 17 | L24: ='📋 SCORECARD'!M10 -> 0 | M24: =IFERROR('📋 SCORECARD'!M10/'📋 SCORECARD'!L10,"") -> 0
A25: 8 | B25: ='📋 SCORECARD'!B11 -> E Magnolia – Knoxville, TN | C25: ='📋 SCORECARD'!C11 -> CENTRAL | D25: ='📋 SCORECARD'!H11 -> 42 | E25: ='📋 SCORECARD'!I11 -> 0 | F25: =IFERROR('📋 SCORECARD'!I11/'📋 SCORECARD'!H11,"") -> 0 | H25: 8 | I25: ='📋 SCORECARD'!B11 -> E Magnolia – Knoxville, TN | J25: ='📋 SCORECARD'!C11 -> CENTRAL | K25: ='📋 SCORECARD'!L11 -> 16 | L25: ='📋 SCORECARD'!M11 -> 0 | M25: =IFERROR('📋 SCORECARD'!M11/'📋 SCORECARD'!L11,"") -> 0
A26: 9 | B26: ='📋 SCORECARD'!B12 -> N Broadway – Knoxville, TN | C26: ='📋 SCORECARD'!C12 -> CENTRAL | D26: ='📋 SCORECARD'!H12 -> 35 | E26: ='📋 SCORECARD'!I12 -> 0 | F26: =IFERROR('📋 SCORECARD'!I12/'📋 SCORECARD'!H12,"") -> 0 | H26: 9 | I26: ='📋 SCORECARD'!B12 -> N Broadway – Knoxville, TN | J26: ='📋 SCORECARD'!C12 -> CENTRAL | K26: ='📋 SCORECARD'!L12 -> 16 | L26: ='📋 SCORECARD'!M12 -> 0 | M26: =IFERROR('📋 SCORECARD'!M12/'📋 SCORECARD'!L12,"") -> 0
A27: 10 | B27: ='📋 SCORECARD'!B13 -> Iyannough Rd., – Hyannis, MA | C27: ='📋 SCORECARD'!C13 -> NE | D27: ='📋 SCORECARD'!H13 -> 36 | E27: ='📋 SCORECARD'!I13 -> 0 | F27: =IFERROR('📋 SCORECARD'!I13/'📋 SCORECARD'!H13,"") -> 0 | H27: 10 | I27: ='📋 SCORECARD'!B13 -> Iyannough Rd., – Hyannis, MA | J27: ='📋 SCORECARD'!C13 -> NE | K27: ='📋 SCORECARD'!L13 -> 9 | L27: ='📋 SCORECARD'!M13 -> 0 | M27: =IFERROR('📋 SCORECARD'!M13/'📋 SCORECARD'!L13,"") -> 0

Sheet 📥 RAW TARGETS
A1: 📥 RAW TARGET DATA | APRIL 2026 | SOURCE: April_Target.xlsx
A2: Store | B2: Loc ID | C2: Voice Acts | D2: Voice Reacts | E2: BTS Acts | F2: BTS Reacts | G2: HSI Acts | H2: HSI Reacts | I2: Magenta/MIM | J2: Total PBB | K2: Bonus Target | L2: Region | M2: Market
A3: W Andrew – Morristown, TN | B3: 10224662 | C3: 39 | D3: 2 | E3: 14 | F3: 2 | G3: 5 | H3: 0 | I3: 7 | J3: 62 | K3: 69 | L3: Metro Central | M3: Metro Knoxville/Johnson City
A4: Colonel Glenn – Little Rock, AR | B4: 10217203 | C4: 47 | D4: 5 | E4: 16 | F4: 2 | G4: 7 | H4: 0 | I4: 8 | J4: 77 | K4: 85 | L4: Metro Central | M4: Metro Little Rock/Fayetteville
A5: Buckland Hills – Manchester, CT | B5: 10223493 | C5: 66 | D5: 12 | E5: 28 | F5: 2 | G5: 8 | H5: 1 | I5: 17 | J5: 117 | K5: 134 | L5: Metro Northeast | M5: Metro CT Hartford
A6: Western Ave – Lynn, MA | B6: 10216464 | C6: 64 | D6: 20 | E6: 35 | F6: 1 | G6: 7 | H6: 1 | I6: 19 | J6: 128 | K6: 147 | L6: Metro Northeast | M6: Metro N Shore MA
A7: Coggeshall St – New Bedford, MA | B7: 10205455 | C7: 73 | D7: 22 | E7: 34 | F7: 1 | G7: 8 | H7: 1 | I7: 28 | J7: 139 | K7: 167 | L7: Metro Northeast | M7: Metro Southeastern MA
A8: Tiogue Ave – Coventry, RI | B8: 10214947 | C8: 31 | D8: 7 | E8: 12 | F8: 0 | G8: 3 | H8: 0 | I8: 11 | J8: 53 | K8: 64 | L8: Metro Northeast | M8: Metro RI Providence
A9: S Frontage – New London, CT | B9: 10203888 | C9: 94 | D9: 22 | E9: 40 | F9: 3 | G9: 9 | H9: 1 | I9: 24 | J9: 169 | K9: 193 | L9: Metro Northeast | M9: Metro CT Hartford
A10: Broadway Newport – Broadway Newport, RI | B10: 10199314 | C10: 50 | D10: 15 | E10: 25 | F10: 1 | G10: 7 | H10: 1 | I10: 15 | J10: 99 | K10: 114 | L10: Metro Northeast | M10: Metro Southeastern MA
A11: Geyer Springs – Little Rock, AR | B11: 10217139 | C11: 94 | D11: 16 | E11: 38 | F11: 2 | G11: 14 | H11: 1 | I11: 17 | J11: 165 | K11: 182 | L11: Metro Central | M11: Metro Little Rock/Fayetteville
A12: Providence Pl – Providence, RI | B12: 10200885 | C12: 107 | D12: 31 | E12: 49 | F12: 2 | G12: 15 | H12: 1 | I12: 35 | J12: 205 | K12: 240 | L12: Metro Northeast | M12: Metro RI Providence
A13: Hartford Ave – Providence, RI | B13: 10230359 | C13: 94 | D13: 27 | E13: 49 | F13: 2 | G13: 9 | H13: 1 | I13: 24 | J13: 182 | K13: 206 | L13: Metro Northeast | M13: Metro RI Providence
A14: Broad St – Providence, RI | B14: 10225631 | C14: 44 | D14: 11 | E14: 19 | F14: 2 | G14: 4 | H14: 0 | I14: 11 | J14: 80 | K14: 91 | L14: Metro Northeast | M14: Metro RI Providence
... A36: W Market – Johnson City, TN | B36: 10222328 | C36: 36 | D36: 9 | E36: 16 | F36: 3 | G36: 5 | H36: 1 | I36: 14 | J36: 70 | K36: 84 | L36: Metro Central | M36: Metro Knoxville/Johnson City

Sheet 📖 HOW TO USE
A1: 📖 HOW TO USE THIS DASHBOARD | EDGE LINK COMMAND CENTER
A4: 🎯 | B4: STEP 1 — ENTER ACTUALS | C4: Go to the 📋 SCORECARD sheet daily
B5: Find the orange/gold cells (ACTUAL columns) | C5: These are the only cells you need to fill in
B6: Enter today's actual numbers for each store | C6: PBB Actual → Column E | BTS Actual → Column I | HSI Actual → Column M
A8: 📊 | B8: STEP 2 — READ THE STATUS | C8: Status updates automatically:
B9: ✅ ON TRACK = ≥90% of target
B10: ⚠️ WATCH = 70–89% of target | C10: Needs a coaching conversation
B11: 🚨 ALERT = <70% of target | C11: Immediate action required
A13: ⚠️ | B13: STEP 3 — READ THE ALERTS | C13: Check the ALERT FLAGS column (Y) on the scorecard
B14: ⚠️ Volume w/o BTS = High boxes, low tablets | C14: Coach the full-solution sell
B15: 🚨 ZERO HSI = No HINT activations | C15: Immediate coaching on WiFi calling pitch
B16: 🚨 ZERO BTS = No BTS activations | C16: Coach tablet attachment
B17: ⚠️ Weak MIMS = Low Magenta in Metro rate | C17: Coach account maximization
A19: 🏆 | B19: STEP 4 — USE THE RANKINGS | C19: Go to 🏆 RANKINGS sheet to see
B20: Top 10 stores across all key metrics | C20: Use winners to replicate behavior
B21: Bottom 10 stores needing attention | C21: These are your coaching priorities
A23: 🎤 | B23: STEP 5 — LEAD YOUR CALLS FROM THIS | C23: Pull from Command Center (🎯 sheet)
B24: Use Director Overview totals as your opening | C24: 'We are at X boxes vs Y goal as a company'
B25: Call out top & bottom performers by name | C25: Accountability drives performance
B26: Use Alert Flags as your coaching script | C26: 'We have a full-solution problem at these 3 stores'
A28: 🔑 | B28: KEY METRICS EXPLAINED
B29: PBB = Total Gross Prepaid Activations | C29: Your primary volume metric
B30: BTS = Tablets activated | C30: Key attachment / solution metric
B31: HSI = Home Internet (HINT) | C31: Highest-value attach
B32: Voice = Voice line activations | C32: Base business driver
B33: MIM = Magenta in Metro | C33: Premium tier conversion

Sheet 👥 STAFFING
A1: 👥 STAFFING SCHEDULE | WEEK OF 3/30 – 4/5/2026 | EDGE LINK INC | 34 STORES
A2: 🟢 Working ⬜ OFF 🟡 Solo Coverage 🔥 Wed 4/1 = APRIL LAUNCH DAY ⚠️ 75 stores have solo-coverage days this week 🚨 6 unstaffed day-slots found!
A3: # | B3: STORE | C3: EMPLOYEE | D3: MON 3/30 | E3: TUE 3/31 | F3: WED 4/1 🔥 | G3: THU 4/2 | H3: FRI 4/3 | I3: SAT 4/4 | J3: SUN 4/5 | K3: TOTAL HRS | L3: HEAD COUNT | M3: SOLO DAYS
A4: 1 | B4: Kelley Sq – Kelley Sq Worcester, MA [NE] | D4: 2 reps | E4: 2 reps | F4: 2 reps | G4: 3 reps | H4: 4 reps | I4: 3 reps | J4: 2 reps | L4: 4 | M4: ✅ Covered
B5: Mariah Gonzalez | C5: AQX90020 | D5: OFF | E5: 11:00-06:00 | F5: OFF | G5: 09:45-06:00 | H5: 12:00-05:00 | I5: OFF | J5: 11:00-03:00 | K5: 24 H 14 M
B6: Richard Foster | C6: OXY97908 | D6: 09:45-06:00 | E6: 09:45-07:00 | F6: 11:00-07:00 | G6: OFF | H6: 11:00-07:00 | I6: 12:00-07:00 | J6: OFF | K6: 40 H 29 M
B7: Alex Correa | C7: RMN54941 | D7: 11:00-07:00 | E7: OFF | F7: 09:45-06:00 | G7: 11:00-07:00 | H7: 09:45-06:00 | I7: 09:45-05:00 | J7: 01:00-06:00 | K7: 44 H 44 M
B8: Juliana Arruda | C8: VIT47142 | D8: OFF | E8: OFF | F8: OFF | G8: 11:00-07:00 | H8: 11:00-07:00 | I8: 11:00-05:00 | J8: OFF | K8: 22 H 0 M
A10: 2 | B10: Providence Pl – Providence, RI [NE] | D10: 2 reps | E10: 2 reps | F10: 2 reps | G10: 2 reps | H10: 3 reps | I10: 3 reps | J10: 0 reps | L10: 5 | M10: 🚨 1 day(s) unstaffed
B11: Abigail Baez | C11: OLP39593 | D11: 10:45-04:00 | E11: OFF | F11: 10:45-06:00 | G11: OFF | H11: 09:45-05:00 | I11: 09:45-04:00 | J11: OFF | K11: 26 H 0 M
B12: Kadisha Rivera | C12: PEJ56713 | D12: OFF | E12: 10:45-06:00 | F12: OFF | G12: 10:45-06:00 | H12: 12:00-09:00 | I12: 12:00-08:00 | J12: OFF | K12: 31 H 30 M
B13: Brandon Mitchell | C13: QQO06195 | D13: OFF | E13: OFF | F13: 01:00-08:00 | G13: 01:00-08:00 | H13: 03:00-09:00 | I13: OFF | J13: OFF | K13: 20 H 0 M
B14: Juliana Arruda | C14: VIT47142 | D14: 01:00-08:00 | E14: 01:00-08:00 | F14: OFF | G14: OFF | H14: OFF | I14: OFF | J14: OFF | K14: 14 H 0 M
B15: Jason Link Jr | C15: YSQ12440 | D15: OFF | E15: OFF | F15: OFF | G15: OFF | H15: OFF | I15: 01:00-09:00 | J15: OFF | K15: 8 H 0 M
A17: 3 | B17: Hartford Ave – Providence, RI [NE] | D17: 2 reps | E17: 2 reps | F17: 2 reps | G17: 2 reps | H17: 3 reps | I17: 2 reps | J17: 1 rep | L17: 3 | M17: ⚠️ 1 solo day(s)
B18: Oscar Mendez Muniz | C18: IAS17194 | D18: OFF | E18: 09:45-07:00 | F18: OFF | G18: 09:45-07:00 | H18: 01:00-07:00 | I18: 09:45-07:00 | J18: OFF | K18: 33 H 44 M
B19: Yanna Soriano | C19: NRG89467 | D19: 09:45-07:00 | E19: 11:00-07:00 | F19: 09:45-07:00 | G19: OFF | H19: 09:45-07:00 | I19: OFF | J19: 10:45-05:00 | K19: 42 H 0 M
B20: Milton Vega | C20: XYL01111 | D20: 11:00-07:00 | E20: OFF | F20: 11:00-07:00 | G20: 11:00-07:00 | H20: 09:45-01:00 | I20: 11:00-07:00 | J20: OFF | K20: 35 H 14 M
A22: 4 | B22: Holyoke Street – Holyoke Street Holyoke, MA [NE] | D22: 2 reps | E22: 2 reps | F22: 2 reps | G22: 2 reps | H22: 2 reps | I22: 3 reps | J22: 2 reps | L22: 3 | M22: ✅ Covered
B23: Carlos Davila | C23: KOW08275 | D23: 11:00-08:00 | E23: 10:00-07:00 | F23: 11:00-08:00 | G23: OFF | H23: OFF | I23: 11:00-09:00 | J23: 11:00-06:00 | K23: 44 H 0 M
B24: Hector Torres | C24: KWV73873 | D24: OFF | E24: 11:00-08:00 | F24: 10:00-07:00 | G24: 11:00-08:00 | H24: 10:00-08:00 | I24: 03:00-08:00 | J24: OFF | K24: 42 H 0 M
B25: Armando Perez | C25: ZIW70174 | D25: 10:00-07:00 | E25: OFF | F25: OFF | G25: 10:00-07:00 | H25: 11:00-09:00 | I25: 10:00-05:00 | J25: 11:00-06:00 | K25: 42 H 0 M
A27: 5 | B27: Granite St – Braintree, MA [NE] | D27: 1 rep | E27: 2 reps | F27: 2 reps | G27: 2 reps | H27: 2 reps | I27: 2 reps | J27: 2 reps | L27: 4 | M27: ⚠️ 1 solo day(s)
B28: Yarele Soler | C28: IFZ56368 | D28: OFF | E28: OFF | F28: 11:00-05:00 | G28: 11:00-05:00 | H28: 11:00-08:00 | I28: 11:00-08:00 | J28: 12:00-05:00 | K28: 35 H 0 M
B29: Abel Burgos | C29: NIV04273 | D29: OFF | E29: 11:00-07:00 | F29: OFF | G29: OFF | H29: OFF | I29: 09:45-09:00 | J29: OFF | K29: 19 H 14 M
B30: Amina Fellah | C30: PNL78523 | D30: OFF | E30: OFF | F30: 09:45-08:00 | G30: 09:45-08:00 | H30: OFF | I30: OFF | J30: OFF | K30: 20 H 30 M
B31: Lucmila Lopes | C31: RLR38159 | D31: 09:45-08:00 | E31: 09:45-08:00 | F31: OFF | G31: OFF | H31: 09:45-09:00 | I31: OFF | J31: 10:45-06:00 | K31: 39 H 0 M
A33: 6 | B33: S Frontage – New London, CT [NE] | D33: 3 reps | E33: 2 reps | F33: 2 reps | G33: 2 reps | H33: 3 reps | I33: 2 reps | J33: 1 rep | L33: 5 | M33: ⚠️ 1 solo day(s)
B34: James Garcia | C34: BPW93549 | D34: 12:00-07:00 | E34: OFF | F34: OFF | G34: OFF | H34: OFF | I34: OFF | J34: OFF | K34: 7 H 0 M
B35: Josh Landry | C35: KWP74551 | D35: OFF | E35: OFF | F35: 09:30-05:00 | G35: 01:00-07:15 | H35: 09:45-04:00 | I35: 09:30-03:00 | J35: OFF | K35: 25 H 30 M
B36: Rashia Oates | C36: NAW86731 | D36: OFF | E36: 12:00-07:00 | F36: OFF | G36: 09:30-07:00 | H36: 01:00-07:00 | I36: OFF | J36: OFF | K36: 22 H 29 M
B37: Shanelle Sanchez | C37: QXM09669 | D37: 09:45-05:30 | E37: 09:45-05:30 | F37: OFF | G37: OFF | H37: OFF | I37: OFF | J37: OFF | K37: 15 H 29 M
B38: Gilberto Alvarez | C38: UAO36325 | D38: 01:00-07:15 | E38: OFF | F38: 11:00-07:15 | G38: OFF | H38: 09:45-07:15 | I38: 11:00-07:15 | J38: 10:45-06:00 | K38: 39 H 30 M
A40: 7 | B40: E Magnolia – Knoxville, TN [CENTRAL] | D40: 2 reps | E40: 2 reps | F40: 2 reps | G40: 2 reps | H40: 2 reps | I40: 2 reps | J40: 2 reps | L40: 3 | M40: ✅ Covered
B41: Melissa Sloane | C41: BZM08410 | D41: OFF | E41: OFF | F41: 09:30-06:00 | G41: OFF | H41: 09:30-06:00 | I41: 09:30-07:00 | J41: 10:30-05:00 | K41: 33 H 0 M
B42: Mariel Mcallister | C42: CSO68288 | D42: 09:30-07:00 | E42: 09:30-07:00 | F42: 11:00-07:00 | G42: 09:30-07:00 | H42: 10:00-07:00 | I42: OFF | J42: OFF | K42: 45 H 29 M
B43: Delbert Phillips | C43: DWE43847 | D43: 01:00-07:00 | E43: 01:00-07:00 | F43: OFF | G43: 01:00-07:00 | H43: OFF | I43: 01:00-07:00 | J43: 12:00-05:00 | K43: 29 H 0 M
A45: 8 | B45: Geyer Springs – Little Rock, AR [CENTRAL] | D45: 2 reps | E45: 2 reps | F45: 2 reps | G45: 2 reps | H45: 2 reps | I45: 2 reps | J45: 1 rep | L45: 4 | M45: ⚠️ 1 solo day(s)
B46: Brenda Serna | C46: CYW45301 | D46: 11:00-07:00 | E46: OFF | F46: OFF | G46: OFF | H46: OFF | I46: OFF | J46: OFF | K46: 8 H 0 M
B47: Karmina Mendoza | C47: IJA97207 | D47: OFF | E47: 09:30-02:30 | F47: 09:30-07:00 | G47: 09:30-07:00 | H47: 09:30-07:00 | I47: 09:30-07:00 | J47: OFF | K47: 43 H 0 M
...
